2025-08-16 10:23:37,785 - exception_logger - ERROR - An exception occured
Traceback (most recent call last):
  File "C:\Users\MyBook Z Series\AppData\Local\Temp\ipykernel_20932\657501396.py", line 12, in log_exception
    1/0
    ~^~
ZeroDivisionError: division by zero
